Workbook

Sheet Circular Template
B2: Instructions | C2: 1. | D2: Fill in green cells below.
B5: Assumptions: | C5: 1. | D5: Mild channel slope.
C6: 2. | D6: Uniform velocity over cross-section.
B8: Conduit
B9: Pipe Diameter (ft) | C9: 0.67
B10: U/S Elev = | C10: 682.19
B11: D/S Elev = | C11: 681.07
B12: Length (ft) = | C12: 99.65
B13: Manning's n = | C13: 0.011
B15: Slope (ft/ft) = | C15: =(C10-C11)/C12 -> 0.011239338
B16: Area full (sf) = | C16: =PI()*(C9/2)^2 -> 0.35256524
B17: Hydraulic Radius full (ft) = | C17: =C16/(PI()*C9) -> 0.1675
B18: V full (fps) = | C18: =(1.486/C13)*(C15^0.5)*C17^(2/3) -> 4.3518411
B19: Q full (cfs) = | C19: =C18*C16 -> 1.5343079 | D19: **note units**
A21: Height (in) | B21: Height (ft) | C21: Area (sf) | D21: Velocity (fps) | E21: Hydraulic Radius (ft) | F21: Top Width (ft) | G21: Flow (cfs) | I21: Proportional Hydraulic Elements (%) | AI21: Known Flows | AJ21: Estimated Depth
I22: Depth | J22: Area | K22: Velocity | L22: Hydraulic Radius | M22: Top Width | N22: Flow | AI22: 0 | AJ22: =AI22^4*$Z$23+AI22^3*$AA$23+AI22^2*$AB$23+AI22*$AC$23+$AD$23 -> 0.029859916
A23: =B23*12 -> 0 | B23: =I23*$C$9 -> 0 | C23: 0 | D23: 0 | E23: =L23*$C$17 -> 0 | F23: =$C$9*M23 -> 8.2084946e-17 | G23: 0 | I23: ='Proportional Element Table'!A3 -> 0 | J23: ='Proportional Element Table'!D3 -> 0 | K23: ='Proportional Element Table'!I3 -> 0 | L23: ='Proportional Element Table'!H3 -> 0 | M23: ='Proportional Element Table'!F3 -> 1.2251485e-16 | N23: ='Proportional Element Table'!J3 -> 0 | Z23: {=LINEST(B23:B58,(G23:G58)^{1,2,3,4},TRUE,FALSE)} -> -0.22498653 | AA23: 0.94691309 | AB23: -1.2894709 | AC23: 0.9214551 | AD23: 0.029859916 | AI23: 5 | AJ23: =AI23^4*$Z$23+AI23^3*$AA$23+AI23^2*$AB$23+AI23*$AC$23+$AD$23 -> -49.852084
A24: =B24*12 -> 0.1608 | B24: =I24*$C$9 -> 0.0134 | C24: =J24*$C$16 -> 0.0016827139 | D24: =K24*$C$18 -> 0.61275174 | E24: =L24*$C$17 -> 0.0088497725 | F24: =$C$9*M24 -> 0.1876 | G24: =N24*$C$19 -> 0.0010310859 | I24: ='Proportional Element Table'!A4 -> 0.02 | J24: ='Proportional Element Table'!D4 -> 0.0047727732 | K24: ='Proportional Element Table'!I4 -> 0.14080288 | L24: ='Proportional Element Table'!H4 -> 0.052834462 | M24: ='Proportional Element Table'!F4 -> 0.28 | N24: ='Proportional Element Table'!J4 -> 0.0006720202 | AI24: 10 | AJ24: =AI24^4*$Z$23+AI24^3*$AA$23+AI24^2*$AB$23+AI24*$AC$23+$AD$23 -> -1422.6549
A25: =B25*12 -> 0.2412 | B25: =I25*$C$9 -> 0.0201 | C25: =J25*$C$16 -> 0.0030819281 | D25: =K25*$C$18 -> 0.80039437 | E25: =L25*$C$17 -> 0.013211779 | F25: =$C$9*M25 -> 0.22858688 | G25: =N25*$C$19 -> 0.0024667579 | I25: ='Proportional Element Table'!A5 -> 0.03 | J25: ='Proportional Element Table'!D5 -> 0.0087414406 | K25: ='Proportional Element Table'!I5 -> 0.18392086 | L25: ='Proportional Element Table'!H5 -> 0.078876294 | M25: ='Proportional Element Table'!F5 -> 0.34117444 | N25: ='Proportional Element Table'!J5 -> 0.0016077333 | AI25: 15 | AJ25: =AI25^4*$Z$23+AI25^3*$AA$23+AI25^2*$AB$23+AI25*$AC$23+$AD$23 -> -8470.3907
A26: =B26*12 -> 0.3216 | B26: =I26*$C$9 -> 0.0268 | C26: =J26*$C$16 -> 0.0047303905 | D26: =K26*$C$18 -> 0.96652288 | E26: =L26*$C$17 -> 0.017531678 | F26: =$C$9*M26 -> 0.2625853 | G26: =N26*$C$19 -> 0.0045720307 | I26: ='Proportional Element Table'!A6 -> 0.04 | J26: ='Proportional Element Table'!D6 -> 0.013417065 | K26: ='Proportional Element Table'!I6 -> 0.22209517 | L26: ='Proportional Element Table'!H6 -> 0.10466673 | M26: ='Proportional Element Table'!F6 -> 0.39191836 | N26: ='Proportional Element Table'!J6 -> 0.0029798652 | AI26: 20 | AJ26: =AI26^4*$Z$23+AI26^3*$AA$23+AI26^2*$AB$23+AI26*$AC$23+$AD$23 -> -28919.87
A27: =B27*12 -> 0.402 | B27: =I27*$C$9 -> 0.0335 | C27: =J27*$C$16 -> 0.0065905149 | D27: =K27*$C$18 -> 1.1179557 | E27: =L27*$C$17 -> 0.021809323 | F27: =$C$9*M27 -> 0.29204623 | G27: =N27*$C$19 -> 0.0073679039 | I27: ='Proportional Element Table'!A7 -> 0.05 | J27: ='Proportional Element Table'!D7 -> 0.018693037 | K27: ='Proportional Element Table'!I7 -> 0.25689259 | L27: ='Proportional Element Table'!H7 -> 0.13020491 | M27: ='Proportional Element Table'!F7 -> 0.43588989 | N27: ='Proportional Element Table'!J7 -> 0.0048021027 | AI27: 25 | AJ27: =AI27^4*$Z$23+AI27^3*$AA$23+AI27^2*$AB$23+AI27*$AC$23+$AD$23 -> -73872.7
A28: =B28*12 -> 0.4824 | B28: =I28*$C$9 -> 0.0402 | C28: =J28*$C$16 -> 0.0086365313 | D28: =K28*$C$18 -> 1.2583687 | E28: =L28*$C$17 -> 0.026044567 | F28: =$C$9*M28 -> 0.31823237 | G28: =N28*$C$19 -> 0.010867941 | I28: ='Proportional Element Table'!A8 -> 0.06 | J28: ='Proportional Element Table'!D8 -> 0.024496265 | K28: ='Proportional Element Table'!I8 -> 0.28915779 | L28: ='Proportional Element Table'!H8 -> 0.15548995 | M28: ='Proportional Element Table'!F8 -> 0.47497368 | N28: ='Proportional Element Table'!J8 -> 0.0070832856 | AI28: 30 | AJ28: =AI28^4*$Z$23+AI28^3*$AA$23+AI28^2*$AB$23+AI28*$AC$23+$AD$23 -> -157805.29
A29: =B29*12 -> 0.5628 | B29: =I29*$C$9 -> 0.0469 | C29: =J29*$C$16 -> 0.010849216 | D29: =K29*$C$18 -> 1.3900319 | E29: =L29*$C$17 -> 0.030237261 | F29: =$C$9*M29 -> 0.341897 | G29: =N29*$C$19 -> 0.015080756 | I29: ='Proportional Element Table'!A9 -> 0.07 | J29: ='Proportional Element Table'!D9 -> 0.030772222 | K29: ='Proportional Element Table'!I9 -> 0.31941239 | L29: ='Proportional Element Table'!H9 -> 0.18052096 | M29: ='Proportional Element Table'!F9 -> 0.51029403 | N29: ='Proportional Element Table'!J9 -> 0.0098290289 | AI29: 35 | AJ29: =AI29^4*$Z$23+AI29^3*$AA$23+AI29^2*$AB$23+AI29*$AC$23+$AD$23 -> -298568.83
A30: =B30*12 -> 0.6432 | B30: =I30*$C$9 -> 0.0536 | C30: =J30*$C$16 -> 0.013213431 | D30: =K30*$C$18 -> 1.5144727 | E30: =L30*$C$17 -> 0.03438725 | F30: =$C$9*M30 -> 0.36353289 | G30: =N30*$C$19 -> 0.020011381 | I30: ='Proportional Element Table'!A10 -> 0.08 | J30: ='Proportional Element Table'!D10 -> 0.037477975 | K30: ='Proportional Element Table'!I10 -> 0.34800736 | L30: ='Proportional Element Table'!H10 -> 0.20529702 | M30: ='Proportional Element Table'!F10 -> 0.5425864 | N30: ='Proportional Element Table'!J10 -> 0.013042611 | AI30: 40 | AJ30: =AI30^4*$Z$23+AI30^3*$AA$23+AI30^2*$AB$23+AI30*$AC$23+$AD$23 -> -517389.35
A31: =B31*12 -> 0.7236 | B31: =I31*$C$9 -> 0.0603 | C31: =J31*$C$16 -> 0.015716799 | D31: =K31*$C$18 -> 1.6327814 | E31: =L31*$C$17 -> 0.03849438 | F31: =$C$9*M31 -> 0.38348356 | G31: =N31*$C$19 -> 0.025662097 | I31: ='Proportional Element Table'!A11 -> 0.09 | J31: ='Proportional Element Table'!D11 -> 0.044578415 | K31: ='Proportional Element Table'!I11 -> 0.37519324 | L31: ='Proportional Element Table'!H11 -> 0.22981719 | M31: ='Proportional Element Table'!F11 -> 0.57236352 | N31: ='Proportional Element Table'!J11 -> 0.01672552 | AI31: 45 | AJ31: =AI31^4*$Z$23+AI31^3*$AA$23+AI31^2*$AB$23+AI31*$AC$23+$AD$23 -> -838867.62
A32: =B32*12 -> 0.804 | B32: =I32*$C$9 -> 0.067 | C32: =J32*$C$16 -> 0.018348912 | D32: =K32*$C$18 -> 1.7457711 | E32: =L32*$C$17 -> 0.04255849 | F32: =$C$9*M32 -> 0.402 | G32: =N32*$C$19 -> 0.032033 | I32: ='Proportional Element Table'!A12 -> 0.1 | J32: ='Proportional Element Table'!D12 -> 0.052044019 | K32: ='Proportional Element Table'!I12 -> 0.4011569 | L32: ='Proportional Element Table'!H12 -> 0.25408054 | M32: ='Proportional Element Table'!F12 -> 0.6 | N32: ='Proportional Element Table'!J12 -> 0.020877818 | AI32: 50 | AJ32: =AI32^4*$Z$23+AI32^3*$AA$23+AI32^2*$AB$23+AI32*$AC$23+$AD$23 -> -1290979.3
A33: =B33*12 -> 0.8844 | B33: =I33*$C$9 -> 0.0737 | C33: =J33*$C$16 -> 0.021100824 | D33: =K33*$C$18 -> 1.8540689 | E33: =L33*$C$17 -> 0.04657942 | F33: =$C$9*M33 -> 0.41927227 | G33: =N33*$C$19 -> 0.039122381 | I33: ='Proportional Element Table'!A13 -> 0.11 | J33: ='Proportional Element Table'!D13 -> 0.059849417 | K33: ='Proportional Element Table'!I13 -> 0.42604242 | L33: ='Proportional Element Table'!H13 -> 0.27808609 | M33: ='Proportional Element Table'!F13 -> 0.62577951 | N33: ='Proportional Element Table'!J13 -> 0.02549839 | AI33: 55 | AJ33: =AI33^4*$Z$23+AI33^3*$AA$23+AI33^2*$AB$23+AI33*$AC$23+$AD$23 -> -1905074.6
A34: =B34*12 -> 0.9648 | B34: =I34*$C$9 -> 0.0804 | C34: =J34*$C$16 -> 0.023964715 | D34: =K34*$C$18 -> 1.9581714 | E34: =L34*$C$17 -> 0.050557003 | F34: =$C$9*M34 -> 0.43544846 | G34: =N34*$C$19 -> 0.046927018 | I34: ='Proportional Element Table'!A14 -> 0.12 | J34: ='Proportional Element Table'!D14 -> 0.067972427 | K34: ='Proportional Element Table'!I14 -> 0.4499639 | L34: ='Proportional Element Table'!H14 -> 0.30183285 | M34: ='Proportional Element Table'!F14 -> 0.64992307 | N34: ='Proportional Element Table'!J14 -> 0.030585138 | AI34: 60 | AJ34: =AI34^4*$Z$23+AI34^3*$AA$23+AI34^2*$AB$23+AI34*$AC$23+$AD$23 -> -2715879
A35: =B35*12 -> 1.0452 | B35: =I35*$C$9 -> 0.0871 | C35: =J35*$C$16 -> 0.02693365 | D35: =K35*$C$18 -> 2.0584803 | E35: =L35*$C$17 -> 0.054491071 | F35: =$C$9*M35 -> 0.4506466 | G35: =N35*$C$19 -> 0.055442389 | I35: ='Proportional Element Table'!A15 -> 0.13 | J35: ='Proportional Element Table'!D15 -> 0.076393381 | K35: ='Proportional Element Table'!I15 -> 0.47301367 | L35: ='Proportional Element Table'!H15 -> 0.32531983 | M35: ='Proportional Element Table'!F15 -> 0.67260687 | N35: ='Proportional Element Table'!J15 -> 0.036135113 | AI35: 65 | AJ35: =AI35^4*$Z$23+AI35^3*$AA$23+AI35^2*$AB$23+AI35*$AC$23+$AD$23 -> -3761492.3
... A58: =B58*12 -> 8.04 | B58: =I58*$C$9 -> 0.67 | C58: =J58*$C$16 -> 0.35256524 | D58: =K58*$C$18 -> 4.3518411 | E58: =L58*$C$17 -> 0.1675 | F58: =$C$9*M58 -> 0 | G58: =N58*$C$19 -> 1.5343079 | I58: ='Proportional Element Table'!A38 -> 1 | J58: ='Proportional Element Table'!D38 -> 1 | K58: ='Proportional Element Table'!I38 -> 1 | L58: ='Proportional Element Table'!H38 -> 1 | M58: ='Proportional Element Table'!F38 -> 0 | N58: ='Proportional Element Table'!J38 -> 1 | AI58: 180 | AJ58: =AI58^4*$Z$23+AI58^3*$AA$23+AI58^2*$AB$23+AI58*$AC$23+$AD$23 -> -2.3070108e+08
AI59: 185 | AJ59: =AI59^4*$Z$23+AI59^3*$AA$23+AI59^2*$AB$23+AI59*$AC$23+$AD$23 -> -2.5758658e+08
AI60: 190 | AJ60: =AI60^4*$Z$23+AI60^3*$AA$23+AI60^2*$AB$23+AI60*$AC$23+$AD$23 -> -2.8675619e+08
AI61: 195 | AJ61: =AI61^4*$Z$23+AI61^3*$AA$23+AI61^2*$AB$23+AI61*$AC$23+$AD$23 -> -3.1833578e+08
AI62: 200 | AJ62: =AI62^4*$Z$23+AI62^3*$AA$23+AI62^2*$AB$23+AI62*$AC$23+$AD$23 -> -3.5245454e+08
AI63: 210 | AJ63: =AI63^4*$Z$23+AI63^3*$AA$23+AI63^2*$AB$23+AI63*$AC$23+$AD$23 -> -4.2884336e+08
AI64: 220 | AJ64: =AI64^4*$Z$23+AI64^3*$AA$23+AI64^2*$AB$23+AI64*$AC$23+$AD$23 -> -5.1702392e+08
AI65: 230 | AJ65: =AI65^4*$Z$23+AI65^3*$AA$23+AI65^2*$AB$23+AI65*$AC$23+$AD$23 -> -6.1815147e+08
AI66: 240 | AJ66: =AI66^4*$Z$23+AI66^3*$AA$23+AI66^2*$AB$23+AI66*$AC$23+$AD$23 -> -7.3343524e+08
AI67: 250 | AJ67: =AI67^4*$Z$23+AI67^3*$AA$23+AI67^2*$AB$23+AI67*$AC$23+$AD$23 -> -8.6413848e+08
AI68: 260 | AJ68: =AI68^4*$Z$23+AI68^3*$AA$23+AI68^2*$AB$23+AI68*$AC$23+$AD$23 -> -1.0115784e+09
...

Sheet Proportional Element Table
A1: Hydraulic Equivalencies for Circular Conduits
A2: Depth/Depth_full | B2: h | C2: Theta | D2: Area/Area_Full | E2: Perimeter/ Perimeter_Full | F2: Top Width (ft) | G2: R | H2: R/R_Full | I2: Velocity | J2: Flow
A3: 0 | B3: =1-A3 -> 1 | C3: =2*ACOS((1/2-B3)/(1/2)) -> 6.2831853 | D3: =(PI()*(1/2)^2-(1/2)^2*(C3-SIN(C3))/2)/(PI()*(1/2)^2) -> 0 | E3: =(2*PI()*(1/2)-(1/2)*C3)/(PI()*1) -> 0 | F3: =SIN(C3/2) -> 1.2251485e-16 | G3: 0 | H3: 0 | I3: =(4*G3/1)^(2/3) -> 0 | J3: =I3*D3 -> 0
A4: 0.02 | B4: =1-A4 -> 0.98 | C4: =2*ACOS((1/2-B4)/(1/2)) -> 5.7155971 | D4: =(PI()*(1/2)^2-(1/2)^2*(C4-SIN(C4))/2)/(PI()*(1/2)^2) -> 0.0047727732 | E4: =(2*PI()*(1/2)-(1/2)*C4)/(PI()*1) -> 0.090334471 | F4: =SIN(C4/2) -> 0.28 | G4: =(PI()*(1/2)^2-(1/2)^2*(C4-SIN(C4))/2)/(2*PI()*(1/2)-(1/2)*C4) -> 0.013208616 | H4: =(PI()*(1/2)^2-(1/2)^2*(C4-SIN(C4))/2)/(2*PI()*(1/2)-(1/2)*C4)/(1/4) -> 0.052834462 | I4: =(4*G4/1)^(2/3) -> 0.14080288 | J4: =I4*D4 -> 0.0006720202
A5: 0.03 | B5: =1-A5 -> 0.97 | C5: =2*ACOS((1/2-B5)/(1/2)) -> 5.5868533 | D5: =(PI()*(1/2)^2-(1/2)^2*(C5-SIN(C5))/2)/(PI()*(1/2)^2) -> 0.0087414406 | E5: =(2*PI()*(1/2)-(1/2)*C5)/(PI()*1) -> 0.11082469 | F5: =SIN(C5/2) -> 0.34117444 | G5: =(PI()*(1/2)^2-(1/2)^2*(C5-SIN(C5))/2)/(2*PI()*(1/2)-(1/2)*C5) -> 0.019719074 | H5: =(PI()*(1/2)^2-(1/2)^2*(C5-SIN(C5))/2)/(2*PI()*(1/2)-(1/2)*C5)/(1/4) -> 0.078876294 | I5: =(4*G5/1)^(2/3) -> 0.18392086 | J5: =I5*D5 -> 0.0016077333
A6: 0.04 | B6: =1-A6 -> 0.96 | C6: =2*ACOS((1/2-B6)/(1/2)) -> 5.4777536 | D6: =(PI()*(1/2)^2-(1/2)^2*(C6-SIN(C6))/2)/(PI()*(1/2)^2) -> 0.013417065 | E6: =(2*PI()*(1/2)-(1/2)*C6)/(PI()*1) -> 0.12818843 | F6: =SIN(C6/2) -> 0.39191836 | G6: =(PI()*(1/2)^2-(1/2)^2*(C6-SIN(C6))/2)/(2*PI()*(1/2)-(1/2)*C6) -> 0.026166683 | H6: =(PI()*(1/2)^2-(1/2)^2*(C6-SIN(C6))/2)/(2*PI()*(1/2)-(1/2)*C6)/(1/4) -> 0.10466673 | I6: =(4*G6/1)^(2/3) -> 0.22209517 | J6: =I6*D6 -> 0.0029798652
A7: 0.05 | B7: =1-A7 -> 0.95 | C7: =2*ACOS((1/2-B7)/(1/2)) -> 5.3811317 | D7: =(PI()*(1/2)^2-(1/2)^2*(C7-SIN(C7))/2)/(PI()*(1/2)^2) -> 0.018693037 | E7: =(2*PI()*(1/2)-(1/2)*C7)/(PI()*1) -> 0.14356629 | F7: =SIN(C7/2) -> 0.43588989 | G7: =(PI()*(1/2)^2-(1/2)^2*(C7-SIN(C7))/2)/(2*PI()*(1/2)-(1/2)*C7) -> 0.032551228 | H7: =(PI()*(1/2)^2-(1/2)^2*(C7-SIN(C7))/2)/(2*PI()*(1/2)-(1/2)*C7)/(1/4) -> 0.13020491 | I7: =(4*G7/1)^(2/3) -> 0.25689259 | J7: =I7*D7 -> 0.0048021027
A8: 0.06 | B8: =1-A8 -> 0.94 | C8: =2*ACOS((1/2-B8)/(1/2)) -> 5.2933171 | D8: =(PI()*(1/2)^2-(1/2)^2*(C8-SIN(C8))/2)/(PI()*(1/2)^2) -> 0.024496265 | E8: =(2*PI()*(1/2)-(1/2)*C8)/(PI()*1) -> 0.15754243 | F8: =SIN(C8/2) -> 0.47497368 | G8: =(PI()*(1/2)^2-(1/2)^2*(C8-SIN(C8))/2)/(2*PI()*(1/2)-(1/2)*C8) -> 0.038872489 | H8: =(PI()*(1/2)^2-(1/2)^2*(C8-SIN(C8))/2)/(2*PI()*(1/2)-(1/2)*C8)/(1/4) -> 0.15548995 | I8: =(4*G8/1)^(2/3) -> 0.28915779 | J8: =I8*D8 -> 0.0070832856
A9: 0.07 | B9: =1-A9 -> 0.93 | C9: =2*ACOS((1/2-B9)/(1/2)) -> 5.212132 | D9: =(PI()*(1/2)^2-(1/2)^2*(C9-SIN(C9))/2)/(PI()*(1/2)^2) -> 0.030772222 | E9: =(2*PI()*(1/2)-(1/2)*C9)/(PI()*1) -> 0.17046343 | F9: =SIN(C9/2) -> 0.51029403 | G9: =(PI()*(1/2)^2-(1/2)^2*(C9-SIN(C9))/2)/(2*PI()*(1/2)-(1/2)*C9) -> 0.04513024 | H9: =(PI()*(1/2)^2-(1/2)^2*(C9-SIN(C9))/2)/(2*PI()*(1/2)-(1/2)*C9)/(1/4) -> 0.18052096 | I9: =(4*G9/1)^(2/3) -> 0.31941239 | J9: =I9*D9 -> 0.0098290289
A10: 0.08 | B10: =1-A10 -> 0.92 | C10: =2*ACOS((1/2-B10)/(1/2)) -> 5.1361591 | D10: =(PI()*(1/2)^2-(1/2)^2*(C10-SIN(C10))/2)/(PI()*(1/2)^2) -> 0.037477975 | E10: =(2*PI()*(1/2)-(1/2)*C10)/(PI()*1) -> 0.18255489 | F10: =SIN(C10/2) -> 0.5425864 | G10: =(PI()*(1/2)^2-(1/2)^2*(C10-SIN(C10))/2)/(2*PI()*(1/2)-(1/2)*C10) -> 0.051324254 | H10: =(PI()*(1/2)^2-(1/2)^2*(C10-SIN(C10))/2)/(2*PI()*(1/2)-(1/2)*C10)/(1/4) -> 0.20529702 | I10: =(4*G10/1)^(2/3) -> 0.34800736 | J10: =I10*D10 -> 0.013042611
A11: 0.09 | B11: =1-A11 -> 0.91 | C11: =2*ACOS((1/2-B11)/(1/2)) -> 5.0644147 | D11: =(PI()*(1/2)^2-(1/2)^2*(C11-SIN(C11))/2)/(PI()*(1/2)^2) -> 0.044578415 | E11: =(2*PI()*(1/2)-(1/2)*C11)/(PI()*1) -> 0.19397337 | F11: =SIN(C11/2) -> 0.57236352 | G11: =(PI()*(1/2)^2-(1/2)^2*(C11-SIN(C11))/2)/(2*PI()*(1/2)-(1/2)*C11) -> 0.057454298 | H11: =(PI()*(1/2)^2-(1/2)^2*(C11-SIN(C11))/2)/(2*PI()*(1/2)-(1/2)*C11)/(1/4) -> 0.22981719 | I11: =(4*G11/1)^(2/3) -> 0.37519324 | J11: =I11*D11 -> 0.01672552
A12: 0.1 | B12: =1-A12 -> 0.9 | C12: =2*ACOS((1/2-B12)/(1/2)) -> 4.9961831 | D12: =(PI()*(1/2)^2-(1/2)^2*(C12-SIN(C12))/2)/(PI()*(1/2)^2) -> 0.052044019 | E12: =(2*PI()*(1/2)-(1/2)*C12)/(PI()*1) -> 0.20483276 | F12: =SIN(C12/2) -> 0.6 | G12: =(PI()*(1/2)^2-(1/2)^2*(C12-SIN(C12))/2)/(2*PI()*(1/2)-(1/2)*C12) -> 0.063520135 | H12: =(PI()*(1/2)^2-(1/2)^2*(C12-SIN(C12))/2)/(2*PI()*(1/2)-(1/2)*C12)/(1/4) -> 0.25408054 | I12: =(4*G12/1)^(2/3) -> 0.4011569 | J12: =I12*D12 -> 0.020877818
A13: 0.11 | B13: =1-A13 -> 0.89 | C13: =2*ACOS((1/2-B13)/(1/2)) -> 4.9309243 | D13: =(PI()*(1/2)^2-(1/2)^2*(C13-SIN(C13))/2)/(PI()*(1/2)^2) -> 0.059849417 | E13: =(2*PI()*(1/2)-(1/2)*C13)/(PI()*1) -> 0.21521903 | F13: =SIN(C13/2) -> 0.62577951 | G13: =(PI()*(1/2)^2-(1/2)^2*(C13-SIN(C13))/2)/(2*PI()*(1/2)-(1/2)*C13) -> 0.069521522 | H13: =(PI()*(1/2)^2-(1/2)^2*(C13-SIN(C13))/2)/(2*PI()*(1/2)-(1/2)*C13)/(1/4) -> 0.27808609 | I13: =(4*G13/1)^(2/3) -> 0.42604242 | J13: =I13*D13 -> 0.02549839
A14: 0.12 | B14: =1-A14 -> 0.88 | C14: =2*ACOS((1/2-B14)/(1/2)) -> 4.8682189 | D14: =(PI()*(1/2)^2-(1/2)^2*(C14-SIN(C14))/2)/(PI()*(1/2)^2) -> 0.067972427 | E14: =(2*PI()*(1/2)-(1/2)*C14)/(PI()*1) -> 0.2251989 | F14: =SIN(C14/2) -> 0.64992307 | G14: =(PI()*(1/2)^2-(1/2)^2*(C14-SIN(C14))/2)/(2*PI()*(1/2)-(1/2)*C14) -> 0.075458213 | H14: =(PI()*(1/2)^2-(1/2)^2*(C14-SIN(C14))/2)/(2*PI()*(1/2)-(1/2)*C14)/(1/4) -> 0.30183285 | I14: =(4*G14/1)^(2/3) -> 0.4499639 | J14: =I14*D14 -> 0.030585138
A15: 0.13 | B15: =1-A15 -> 0.87 | C15: =2*ACOS((1/2-B15)/(1/2)) -> 4.8077334 | D15: =(PI()*(1/2)^2-(1/2)^2*(C15-SIN(C15))/2)/(PI()*(1/2)^2) -> 0.076393381 | E15: =(2*PI()*(1/2)-(1/2)*C15)/(PI()*1) -> 0.23482547 | F15: =SIN(C15/2) -> 0.67260687 | G15: =(PI()*(1/2)^2-(1/2)^2*(C15-SIN(C15))/2)/(2*PI()*(1/2)-(1/2)*C15) -> 0.081329957 | H15: =(PI()*(1/2)^2-(1/2)^2*(C15-SIN(C15))/2)/(2*PI()*(1/2)-(1/2)*C15)/(1/4) -> 0.32531983 | I15: =(4*G15/1)^(2/3) -> 0.47301367 | J15: =I15*D15 -> 0.036135113
... A38: 1 | B38: =1-A38 -> 0 | C38: =2*ACOS((1/2-B38)/(1/2)) -> 0 | D38: =(PI()*(1/2)^2-(1/2)^2*(C38-SIN(C38))/2)/(PI()*(1/2)^2) -> 1 | E38: =(2*PI()*(1/2)-(1/2)*C38)/(PI()*1) -> 1 | F38: =SIN(C38/2) -> 0 | G38: =(PI()*(1/2)^2-(1/2)^2*(C38-SIN(C38))/2)/(2*PI()*(1/2)-(1/2)*C38) -> 0.25 | H38: =(PI()*(1/2)^2-(1/2)^2*(C38-SIN(C38))/2)/(2*PI()*(1/2)-(1/2)*C38)/(1/4) -> 1 | I38: =(4*G38/1)^(2/3) -> 1 | J38: =I38*D38 -> 1
